```scala
import scala.concurrent.{ExecutionContext, Future}

class MyClass(implicit ec: ExecutionContext) {
  def myMethod(i: Int): Future[Int] = Future {
    if (i < 0) throw new IllegalArgumentException("Input must be non-negative")
    i * 2
  }
}

//This code causes an error when the input is negative because the exception is not handled properly in the future, which results in the future being completed with a failure.
// Correct implementation is to handle exception properly with recover or recoverWith, example below

class MyClassImproved(implicit ec: ExecutionContext) {
  def myMethodImproved(i: Int): Future[Int] = Future {
    if (i < 0) throw new IllegalArgumentException("Input must be non-negative")
    i * 2
  }.recover {
    case e: IllegalArgumentException => 0 // Handle exception with default value 0
  }
}
```